<?xml version="1.0" encoding="UTF-8"?>
<!-- Generated by org.testng.reporters.JUnitReportReporter -->
<testsuite hostname="TrexaiiMae" failures="1" tests="4" name="FrameworkPractice.ErrorValidations" time="17.375" errors="0" timestamp="20 Aug 2024 03:23:22 GMT" skipped="2">
  <testcase classname="FrameworkPractice.ErrorValidations" name="ErrorValidation" time="3.418">
    <skipped/>
  </testcase> <!-- ErrorValidation -->
  <testcase classname="FrameworkPractice.ErrorValidations" name="ErrorValidation" time="3.269">
    <skipped/>
  </testcase> <!-- ErrorValidation -->
  <testcase classname="FrameworkPractice.ErrorValidations" name="ErrorValidation" time="3.691">
    <failure message="expected [Incorrect email or password.] but found [Incorrect email or passwordsss.]" type="java.lang.AssertionError">
      <![CDATA[java.lang.AssertionError: expected [Incorrect email or password.] but found [Incorrect email or passwordsss.]
at org.testng.Assert.fail(Assert.java:96)
at org.testng.Assert.failNotEquals(Assert.java:776)
at org.testng.Assert.assertEqualsImpl(Assert.java:137)
at org.testng.Assert.assertEquals(Assert.java:118)
at org.testng.Assert.assertEquals(Assert.java:453)
at org.testng.Assert.assertEquals(Assert.java:463)
at FrameworkPractice.ErrorValidations.ErrorValidation(ErrorValidations.java:26)
at java.base/jdk.internal.reflect.NativeMethodAccessorImpl.invoke0(Native Method)
at java.base/jdk.internal.reflect.NativeMethodAccessorImpl.invoke(NativeMethodAccessorImpl.java:62)
at java.base/jdk.internal.reflect.DelegatingMethodAccessorImpl.invoke(DelegatingMethodAccessorImpl.java:43)
at java.base/java.lang.reflect.Method.invoke(Method.java:566)
at org.testng.internal.MethodInvocationHelper.invokeMethod(MethodInvocationHelper.java:124)
at org.testng.internal.Invoker.invokeMethod(Invoker.java:583)
at org.testng.internal.Invoker.retryFailed(Invoker.java:839)
at org.testng.internal.Invoker.invokeTestMethods(Invoker.java:1010)
at org.testng.internal.TestMethodWorker.invokeTestMethods(TestMethodWorker.java:125)
at org.testng.internal.TestMethodWorker.run(TestMethodWorker.java:109)
at org.testng.TestRunner.privateRun(TestRunner.java:648)
at org.testng.TestRunner.run(TestRunner.java:505)
at org.testng.SuiteRunner.runTest(SuiteRunner.java:455)
at org.testng.SuiteRunner.access$000(SuiteRunner.java:40)
at org.testng.SuiteRunner$SuiteWorker.run(SuiteRunner.java:489)
at org.testng.internal.thread.ThreadUtil$1.call(ThreadUtil.java:52)
at java.base/java.util.concurrent.FutureTask.run(FutureTask.java:264)
at java.base/java.util.concurrent.ThreadPoolExecutor.runWorker(ThreadPoolExecutor.java:1128)
at java.base/java.util.concurrent.ThreadPoolExecutor$Worker.run(ThreadPoolExecutor.java:628)
at java.base/java.lang.Thread.run(Thread.java:834)
]]>
    </failure>
  </testcase> <!-- ErrorValidation -->
  <testcase classname="FrameworkPractice.ErrorValidations" name="producterror" time="6.997"/>
</testsuite> <!-- FrameworkPractice.ErrorValidations -->
